<robot name="dodo_model" version="1.0">
  <joint name="back_caster_link_joint" type="continuous">
    <limit lower="0" upper="0" effort="0.00000" velocity="0.00000"/>
    <origin rpy="-0.00000 0.00000 0.00000" xyz="-0.19276 0.00000 0.00000"/>
    <parent link="body_link"/>
    <child link="back_caster_link"/>
    <axis xyz="0.00000 0.00000 1.00000"/>
  </joint>
  <joint name="front_caster_link_joint" type="continuous">
    <limit lower="0" upper="0" effort="0.00000" velocity="0.00000"/>
    <origin rpy="-0.00000 0.00000 0.00000" xyz="0.19276 0.00000 0.00000"/>
    <parent link="body_link"/>
    <child link="front_caster_link"/>
    <axis xyz="0.00000 0.00000 1.00000"/>
  </joint>
  <joint name="left_wheel_link_joint" type="continuous">
    <limit lower="0" upper="0" effort="0.00000" velocity="0.00000"/>
    <origin rpy="3.14159 0.00000 3.14159" xyz="0.00000 0.19578 0.01022"/>
    <parent link="body_link"/>
    <child link="left_wheel_link"/>
    <axis xyz="0.00000 0.00000 1.00000"/>
  </joint>
  <joint name="right_wheel_link_joint" type="continuous">
    <limit lower="0" upper="0" effort="0.00000" velocity="0.00000"/>
    <origin rpy="1.53589 0.00000 0.00000" xyz="0.00000 -0.19578 0.01059"/>
    <parent link="body_link"/>
    <child link="right_wheel_link"/>
    <axis xyz="0.00000 0.00000 1.00000"/>
  </joint>
  <link name="back_caster_link">
    <collision name="back_caster_collision">
      <origin rpy="0.00000 0.00000 0.00000" xyz="0.00000 0.00000 0.00000"/>
      <geometry>
        <sphere radius="0.05196"/>
      </geometry>
    </collision>
    <visual name="back_caster">
      <origin rpy="0.00000 0.00000 0.00000" xyz="0.00000 0.00000 0.00000"/>
      <geometry>
        <sphere radius="0.03000"/>
      </geometry>
    </visual>
  </link>
  <link name="body_link">
    <collision name="body_collision">
      <origin rpy="-0.00000 0.00000 0.00000" xyz="0.00039 0.00000 0.45238"/>
      <geometry>
        <cylinder radius="0.27358" length="0.89942"/>
      </geometry>
    </collision>
    <inertial>
      <inertia ixx="0.00500" ixy="0.00000" ixz="0.00000" iyy="0.00500" iyz="0.00000" izz="0.00500"/>
      <origin rpy="0.00000 0.00000 0.00000" xyz="0.00000 0.00000 0.00000"/>
      <mass value="0.00500"/>
    </inertial>
    <visual name="body">
      <origin rpy="0.00000 0.00000 0.00000" xyz="0.00000 0.00000 0.00000"/>
      <material name="Material.001"/>
      <geometry>
        <mesh filename="../meshes/stl/Cylinder.stl" scale="0.26000 0.26000 0.12844"/>
      </geometry>
    </visual>
  </link>
  <link name="front_caster_link">
    <collision name="front_caster_collision">
      <origin rpy="0.00000 0.00000 0.00000" xyz="0.00000 0.00000 0.00000"/>
      <geometry>
        <sphere radius="0.05196"/>
      </geometry>
    </collision>
    <visual name="front_caster">
      <origin rpy="0.00000 0.00000 0.00000" xyz="0.00000 0.00000 0.00000"/>
      <geometry>
        <sphere radius="0.03000"/>
      </geometry>
    </visual>
  </link>
  <link name="left_wheel_link">
    <collision name="left_wheel_collision">
      <origin rpy="3.14157 -0.00122 -3.14157" xyz="0.00000 0.00000 -0.00000"/>
      <geometry>
        <cylinder radius="0.05000" length="0.10000"/>
      </geometry>
    </collision>
    <visual name="left_wheel">
      <origin rpy="0.00000 0.00000 3.14159" xyz="0.00000 0.00000 -0.00000"/>
      <geometry>
        <cylinder radius="0.04000" length="0.02000"/>
      </geometry>
    </visual>
  </link>
  <link name="right_wheel_link">
    <collision name="right_wheel_collision">
      <origin rpy="0.03489 0.00122 -0.03489" xyz="0.00000 -0.00000 -0.00000"/>
      <geometry>
        <cylinder radius="0.05000" length="0.10000"/>
      </geometry>
    </collision>
    <visual name="right_wheel">
      <origin rpy="0.00000 0.00000 0.00000" xyz="0.00000 -0.00000 -0.00000"/>
      <geometry>
        <cylinder radius="0.04000" length="0.02000"/>
      </geometry>
    </visual>
  </link>
  <material name="Material.001">
    <color rgba="0.80000 0.80000 0.80000 1.00000"/>
  </material>
</robot>